Workbook

Sheet 现金流量表
B1: 现金流量表（适用执行企业会计准则的一般企业）
E2: 会企03表 单位：元
B3: 纳税人识别号 | C3: =IF(#REF!="","",#REF!) -> #REF! | D3: 纳税人名称 | E3: =IF(#REF!="","",#REF!) -> #REF!
B4: 所属期起 | C4: =IF(#REF!="","",#REF!) -> #REF! | D4: 所属期止 | E4: =IF(#REF!="","",#REF!) -> #REF!
B5: 项目 | C5: 本期金额 | D5: 上期金额
B6: 一、经营活动产生的现金流量：
B7: 销售商品、提供劳务收到的现金 | C7: 0 | D7: 0
B8: 收到的税费返还 | C8: 0 | D8: 0
B9: 收到其他与经营活动有关的现金 | C9: 0 | D9: 0
B10: 经营活动现金流入小计 | C10: =ROUND(SUM(现金流量表!C7:C9),2) -> 0 | D10: =ROUND(SUM(现金流量表!D7:D9),2) -> 0
B11: 购买商品、接受劳务支付的现金 | C11: 0 | D11: 0
B12: 支付给职工以及为职工支付的现金 | C12: 0 | D12: 0
B13: 支付的各项税费 | C13: 0 | D13: 0
B14: 支付其他与经营活动有关的现金 | C14: 0 | D14: 0
B15: 经营活动现金流出小计 | C15: =ROUND(SUM(现金流量表!C11:C14),2) -> 0 | D15: =ROUND(SUM(现金流量表!D11:D14),2) -> 0
B16: 经营活动产生的现金流量净额 | C16: =ROUND(现金流量表!C10-现金流量表!C15,2) -> 0 | D16: =ROUND(现金流量表!D10-现金流量表!D15,2) -> 0
B17: 二、投资活动产生的现金流量：
B18: 收回投资收到的现金 | C18: 0 | D18: 0
B19: 取得投资收益收到的现金 | C19: 0 | D19: 0
B20: 处置固定资产、无形资产和其他长期资产收回的现金净额 | C20: 0 | D20: 0
B21: 处置子公司及其他营业单位收到的现金净额 | C21: 0 | D21: 0
B22: 收到其他与投资活动有关的现金 | C22: 0 | D22: 0
B23: 投资活动现金流入小计 | C23: =ROUND(SUM(现金流量表!C18:C22),2) -> 0 | D23: =ROUND(SUM(现金流量表!D18:D22),2) -> 0
B24: 购建固定资产、无形资产和其他长期资产支付的现金 | C24: 0 | D24: 0
B25: 投资支付的现金 | C25: 0 | D25: 0
B26: 取得子公司及其他营业单位支付的现金净额 | C26: 0 | D26: 0
B27: 支付其他与投资活动有关的现金 | C27: 0 | D27: 0
B28: 投资活动现金流出小计 | C28: =ROUND(SUM(现金流量表!C24:C27),2) -> 0 | D28: =ROUND(SUM(现金流量表!D24:D27),2) -> 0
B29: 投资活动产生的现金流量净额 | C29: =ROUND(现金流量表!C23-现金流量表!C28,2) -> 0 | D29: =ROUND(现金流量表!D23-现金流量表!D28,2) -> 0
B30: 三、筹资活动产生的现金流量：
B31: 吸收投资收到的现金 | C31: 0 | D31: 0
B32: 取得借款收到的现金 | C32: 0 | D32: 0
B33: 收到其他与筹资活动有关的现金 | C33: 0 | D33: 0
B34: 筹资活动现金流入小计 | C34: =ROUND(SUM(现金流量表!C31:C33),2) -> 0 | D34: =ROUND(SUM(现金流量表!D31:D33),2) -> 0
B35: 偿还债务支付的现金 | C35: 0 | D35: 0
B36: 分配股利、利润或偿付利息支付的现金 | C36: 0 | D36: 0
B37: 支付其他与筹资活动有关的现金 | C37: 0 | D37: 0
B38: 筹资活动现金流出小计 | C38: =ROUND(SUM(现金流量表!C35:C37),2) -> 0 | D38: =ROUND(SUM(现金流量表!D35:D37),2) -> 0
B39: 筹资活动产生的现金流量净额 | C39: =ROUND(现金流量表!C34-现金流量表!C38,2) -> 0 | D39: =ROUND(现金流量表!D34-现金流量表!D38,2) -> 0
B40: 四、汇率变动对现金及现金等价物的影响 | C40: 0 | D40: 0
...

Sheet 一般企业_已执行
